Workbook

Sheet Sheet1
B2: Keterangan | C2: ADMR | D2: ADRO | E2: AKRA | F2: ITMG | G2: MEDC | H2: PGAS | I2: PTBA
B3: Satuan | C3: 1 | D3: 1000 | E3: 1000 | F3: 1000 | G3: 1 | H3: 1 | I3: 1000000
B4: Tanggal laporan audit atau hasil laporan review | C4: 45715 | D4: 45716 | E4: 45734 | F4: 45714 | G4: 45744 | H4: 45737 | I4: 45742
B5: Kurs Konversi | C5: 16162 | D5: 16162 | E5: 1 | F5: 16260 | G5: 16162 | H5: 16157 | I5: 1
B6: Jumlah Aset | C6: 2073594757 | D6: 6702127 | E6: 33108684368 | F6: 2406544 | G6: 7926890365 | H6: 6415949730 | I6: 41854334
B7: Jumlah Liabilitas | C7: 571331203 | D7: 1331295 | E7: 18484691894 | F7: 472734 | G7: 5575858796 | H7: 2744422446 | I7: 19210522
B8: Jumlah ekuitas | C8: 1502263554 | D8: 5370832 | E8: 14623992474 | F8: 1933810 | G8: 2351031569 | H8: 3671527284 | I8: 22643812
B9: Jumlah ekuitas yang diatribusikan kepada pemilik entitas induk | C9: 1411313792 | D9: 4926856 | E9: 11562536639 | F9: 1928067 | G9: 2118726151 | H9: 2826045922 | I9: 22505288
B10: Jumlah laba | C10: 434769398 | D10: 1556132 | E10: 2399467512 | F10: 375601 | G10: 380206515 | H10: 439637270 | I10: 5139423
B11: Laba yang dapat diatribusikan ke entitas induk | C11: 436656873 | D11: 1380013 | E11: 2225117975 | F11: 374119 | G11: 367358268 | H11: 339427774 | I11: 5103720
B12: Laba per saham | C12: 0.0107 | D12: 0.01855 | E12: 112.73 | F12: 0.33 | G12: 0.01472 | H12: 0.014001925 | I12: 444
B13: ="Harga Saham "&TEXT(Sheet2!F13,"DD MMM YYYY") -> Harga Saham 08 Apr 2025 | C13: =VLOOKUP(C2,Sheet2!$E$13:$G$19,3,0) -> 790 | D13: =VLOOKUP(D2,Sheet2!$E$13:$G$19,3,0) -> 1645 | E13: =VLOOKUP(E2,Sheet2!$E$13:$G$19,3,0) -> 970 | F13: =VLOOKUP(F2,Sheet2!$E$13:$G$19,3,0) -> 21825 | G13: =VLOOKUP(G2,Sheet2!$E$13:$G$19,3,0) -> 970 | H13: =VLOOKUP(H2,Sheet2!$E$13:$G$19,3,0) -> 1445 | I13: =VLOOKUP(I2,Sheet2!$E$13:$G$19,3,0) -> 2420
B14: ROA | C14: =C10/C6 -> 0.20966941 | D14: =D10/D6 -> 0.2321848 | E14: =E10/E6 -> 0.072472451 | F14: =F10/F6 -> 0.15607485 | G14: =G10/G6 -> 0.047964145 | H14: =H10/H6 -> 0.068522555 | I14: =I10/I6 -> 0.12279309
B15: DER | C15: =C7/C8 -> 0.38031356 | D15: =D7/D8 -> 0.247875 | E15: =E7/E8 -> 1.2639976 | F15: =F7/F8 -> 0.24445731 | G15: =G7/G8 -> 2.3716648 | H15: =H7/H8 -> 0.74748796 | I15: =I7/I8 -> 0.84837844
B16: EPS | C16: =C12*C5 -> 172.9334 | D16: =D12*D5 -> 299.8051 | E16: =E12*E5 -> 112.73 | F16: =F12*F5 -> 5365.8 | G16: =G12*G5 -> 237.90464 | H16: =H12*H5 -> 226.2291 | I16: =I12*I5 -> 444 | K16: =K12*K5 -> 0
B17: Jumlah Saham Beredar | C17: =C11/C12 -> 4.0809054e+10 | D17: =D11*D3/D12 -> 7.4394232e+10 | E17: =E11*E3/E12 -> 1.9738472e+10 | F17: =F11*F3/F12 -> 1.1336939e+09 | G17: =G11*G3/G12 -> 2.4956404e+10 | H17: =H11*H3/H12 -> 2.4241508e+10 | I17: =I11*I3/I12 -> 1.1494865e+10
B18: BVPS | C18: =C9/C17*C5 -> 558.93611 | D18: =D9*D3/D17*D5 -> 1070.3497 | E18: =E9*E3/E17*E5 -> 585.78681 | F18: =F9*F3/F17*F5 -> 27653.292 | G18: =G9*G3/G17*G5 -> 1372.1068 | H18: =H9*H3/H17*H5 -> 1883.5637 | I18: =I9*I3/I17*I5 -> 1957.8558
B19: PBV | C19: =C13/C18 -> 1.4133995 | D19: =D13/D18 -> 1.5368808 | E19: =E13/E18 -> 1.6558925 | F19: =F13/F18 -> 0.78923696 | G19: =G13/G18 -> 0.70694205 | H19: =H13/H18 -> 0.76716281 | I19: =I13/I18 -> 1.2360461
B20: Graham Number (nilai intrinsik) | C20: =SQRT(22.5*C16*C18) -> 1474.7275 | D20: =SQRT(22.5*D16*D18) -> 2687.0368 | E20: =SQRT(22.5*E16*E18) -> 1218.9357 | F20: =SQRT(22.5*F16*F18) -> 57780.583 | G20: =SQRT(22.5*G16*G18) -> 2710.1085 | H20: =SQRT(22.5*H16*H18) -> 3096.3899 | I20: =SQRT(22.5*I16*I18) -> 4422.5535
B21: Klasifikasi Graham Number | C21: =IF(C13>C20,"Overvalued","Undervalued") -> Undervalued | D21: =IF(D13>D20,"Overvalued","Undervalued") -> Undervalued | E21: =IF(E13>E20,"Overvalued","Undervalued") -> Undervalued | F21: =IF(F13>F20,"Overvalued","Undervalued") -> Undervalued | G21: =IF(G13>G20,"Overvalued","Undervalued") -> Undervalued | H21: =IF(H13>H20,"Overvalued","Undervalued") -> Undervalued | I21: =IF(I13>I20,"Overvalued","Undervalued") -> Undervalued
B23: ENTROPY
B25: SUMMARY | C25: KODE | D25: ROA | E25: DER | F25: PBV | G25: EPS
C26: {=_xlfn.UNIQUE(TRANSPOSE($C$2:$I$2))} -> ADMR | D26: =HLOOKUP($C26,$C$2:$I$21,MATCH(D$25,$B$2:$B$21,0))*100 -> 20.966941 | E26: =HLOOKUP($C26,$C$2:$I$21,MATCH(E$25,$B$2:$B$21,0)) -> 0.38031356 | F26: =HLOOKUP($C26,$C$2:$I$21,MATCH(F$25,$B$2:$B$21,0)) -> 1.4133995 | G26: =HLOOKUP($C26,$C$2:$I$21,MATCH(G$25,$B$2:$B$21,0)) -> 172.9334
C27: ADRO | D27: =HLOOKUP($C27,$C$2:$I$21,MATCH(D$25,$B$2:$B$21,0))*100 -> 23.21848 | E27: =HLOOKUP($C27,$C$2:$I$21,MATCH(E$25,$B$2:$B$21,0)) -> 0.247875 | F27: =HLOOKUP($C27,$C$2:$I$21,MATCH(F$25,$B$2:$B$21,0)) -> 1.5368808 | G27: =HLOOKUP($C27,$C$2:$I$21,MATCH(G$25,$B$2:$B$21,0)) -> 299.8051
C28: AKRA | D28: =HLOOKUP($C28,$C$2:$I$21,MATCH(D$25,$B$2:$B$21,0))*100 -> 7.2472451 | E28: =HLOOKUP($C28,$C$2:$I$21,MATCH(E$25,$B$2:$B$21,0)) -> 1.2639976 | F28: =HLOOKUP($C28,$C$2:$I$21,MATCH(F$25,$B$2:$B$21,0)) -> 1.6558925 | G28: =HLOOKUP($C28,$C$2:$I$21,MATCH(G$25,$B$2:$B$21,0)) -> 112.73
C29: ITMG | D29: =HLOOKUP($C29,$C$2:$I$21,MATCH(D$25,$B$2:$B$21,0))*100 -> 15.607485 | E29: =HLOOKUP($C29,$C$2:$I$21,MATCH(E$25,$B$2:$B$21,0)) -> 0.24445731 | F29: =HLOOKUP($C29,$C$2:$I$21,MATCH(F$25,$B$2:$B$21,0)) -> 0.78923696 | G29: =HLOOKUP($C29,$C$2:$I$21,MATCH(G$25,$B$2:$B$21,0)) -> 5365.8
C30: MEDC | D30: =HLOOKUP($C30,$C$2:$I$21,MATCH(D$25,$B$2:$B$21,0))*100 -> 4.7964145 | E30: =HLOOKUP($C30,$C$2:$I$21,MATCH(E$25,$B$2:$B$21,0)) -> 2.3716648 | F30: =HLOOKUP($C30,$C$2:$I$21,MATCH(F$25,$B$2:$B$21,0)) -> 0.70694205 | G30: =HLOOKUP($C30,$C$2:$I$21,MATCH(G$25,$B$2:$B$21,0)) -> 237.90464
C31: PGAS | D31: =HLOOKUP($C31,$C$2:$I$21,MATCH(D$25,$B$2:$B$21,0))*100 -> 6.8522555 | E31: =HLOOKUP($C31,$C$2:$I$21,MATCH(E$25,$B$2:$B$21,0)) -> 0.74748796 | F31: =HLOOKUP($C31,$C$2:$I$21,MATCH(F$25,$B$2:$B$21,0)) -> 0.76716281 | G31: =HLOOKUP($C31,$C$2:$I$21,MATCH(G$25,$B$2:$B$21,0)) -> 226.2291
C32: PTBA | D32: =HLOOKUP($C32,$C$2:$I$21,MATCH(D$25,$B$2:$B$21,0))*100 -> 12.279309 | E32: =HLOOKUP($C32,$C$2:$I$21,MATCH(E$25,$B$2:$B$21,0)) -> 0.84837844 | F32: =HLOOKUP($C32,$C$2:$I$21,MATCH(F$25,$B$2:$B$21,0)) -> 1.2360461 | G32: =HLOOKUP($C32,$C$2:$I$21,MATCH(G$25,$B$2:$B$21,0)) -> 444
C34: TOTAL | D34: =SUM(D26:D32) -> 90.968131 | E34: =SUM(E26:E32) -> 6.1041747 | F34: =SUM(F26:F32) -> 8.1055607 | G34: =SUM(G26:G32) -> 6859.4022
B36: Pij | C36: KODE | D36: ROA | E36: DER | F36: PBV | G36: EPS
C37: {=_xlfn.UNIQUE(TRANSPOSE($C$2:$I$2))} -> ADMR | D37: =D26/D$34 -> 0.23048667 | E37: =E26/E$34 -> 0.062303846 | F37: =F26/F$34 -> 0.17437405 | G37: =G26/G$34 -> 0.025211147
C38: ADRO | D38: =D27/D$34 -> 0.25523752 | E38: =E27/E$34 -> 0.040607456 | F38: =F27/F$34 -> 0.18960821 | G38: =G27/G$34 -> 0.043707176
C39: AKRA | D39: =D28/D$34 -> 0.079667957 | E39: =E28/E$34 -> 0.20707101 | F39: =F28/F$34 -> 0.20429093 | G39: =G28/G$34 -> 0.016434377
C40: ITMG | D40: =D29/D$34 -> 0.17157091 | E40: =E29/E$34 -> 0.040047562 | F40: =F29/F$34 -> 0.097369816 | G40: =G29/G$34 -> 0.78225475
C41: MEDC | D41: =D30/D$34 -> 0.052726317 | E41: =E30/E$34 -> 0.3885316 | F41: =F30/F$34 -> 0.087216921 | G41: =G30/G$34 -> 0.034682999
C42: PGAS | D42: =D31/D$34 -> 0.075325891 | E42: =E31/E$34 -> 0.1224552 | F42: =F31/F$34 -> 0.094646483 | G42: =G31/G$34 -> 0.032980877
C43: PTBA | D43: =D32/D$34 -> 0.13498474 | E43: =E32/E$34 -> 0.13898332 | F43: =F32/F$34 -> 0.15249359 | G43: =G32/G$34 -> 0.064728672
C45: TOTAL | D45: =SUM(D37:D43) -> 1 | E45: =SUM(E37:E43) -> 1 | F45: =SUM(F37:F43) -> 1 | G45: =SUM(G37:G43) -> 1
B47: LN Pij | C47: KODE | D47: ROA | E47: DER | F47: PBV | G47: EPS
...

Sheet Sheet2
B2: Ticker Actual_Date_2025-04-01 Close_2025-04-01 Actual_Date_2025-09-01 \ | E2: {=_xlfn.TEXTSPLIT(TRIM(B2)," ")} -> Ticker | F2: Actual_Date_2025-04-01 | G2: Close_2025-04-01 | H2: Actual_Date_2025-09-01 | I2: \ | K2: {=_xlfn.TEXTSPLIT(TRIM(B11)," ")} -> Close_2025-09-01 | L2: Actual_Date_2026-04-01 | M2: Close_2026-04-01 | N2: =F3&" VS "&H3 -> 2025-04-08 VS 2025-09-01 | O2: =F3&" VS "&L3 -> 2025-04-08 VS 2026-04-01
B3: 0 ADRO.JK 2025-04-08 1645.0 2025-09-01 | D3: {=_xlfn.TEXTSPLIT(TRIM(B3)," ")} -> 0 | E3: ADRO.JK | F3: 2025-04-08 | G3: 1645.0 | H3: 2025-09-01 | J3: {=_xlfn.TEXTSPLIT(TRIM(B12)," ")} -> 0 | K3: 1720.0 | L3: 2026-04-01 | M3: 2490.0 | N3: =K3/G3-1 -> 0.045592705 | O3: =M3/G3-1 -> 0.51367781
B4: 1 ADMR.JK 2025-04-08 790.0 2025-09-01 | D4: {=_xlfn.TEXTSPLIT(TRIM(B4)," ")} -> 1 | E4: ADMR.JK | F4: 2025-04-08 | G4: 790.0 | H4: 2025-09-01 | J4: {=_xlfn.TEXTSPLIT(TRIM(B13)," ")} -> 1 | K4: 990.0 | L4: 2026-04-01 | M4: 2010.0 | N4: =K4/G4-1 -> 0.25316456 | O4: =M4/G4-1 -> 1.5443038
B5: 2 AKRA.JK 2025-04-08 970.0 2025-09-01 | D5: {=_xlfn.TEXTSPLIT(TRIM(B5)," ")} -> 2 | E5: AKRA.JK | F5: 2025-04-08 | G5: 970.0 | H5: 2025-09-01 | J5: {=_xlfn.TEXTSPLIT(TRIM(B14)," ")} -> 2 | K5: 1190.0 | L5: 2026-04-01 | M5: 1345.0 | N5: =K5/G5-1 -> 0.22680412 | O5: =M5/G5-1 -> 0.38659794
B6: 3 ITMG.JK 2025-04-08 21825.0 2025-09-01 | D6: {=_xlfn.TEXTSPLIT(TRIM(B6)," ")} -> 3 | E6: ITMG.JK | F6: 2025-04-08 | G6: 21825.0 | H6: 2025-09-01 | J6: {=_xlfn.TEXTSPLIT(TRIM(B15)," ")} -> 3 | K6: 22200.0 | L6: 2026-04-01 | M6: 27775.0 | N6: =K6/G6-1 -> 0.017182131 | O6: =M6/G6-1 -> 0.27262314
B7: 4 MEDC.JK 2025-04-08 970.0 2025-09-01 | D7: {=_xlfn.TEXTSPLIT(TRIM(B7)," ")} -> 4 | E7: MEDC.JK | F7: 2025-04-08 | G7: 970.0 | H7: 2025-09-01 | J7: {=_xlfn.TEXTSPLIT(TRIM(B16)," ")} -> 4 | K7: 1135.0 | L7: 2026-04-01 | M7: 1685.0 | N7: =K7/G7-1 -> 0.17010309 | O7: =M7/G7-1 -> 0.7371134
B8: 5 PGAS.JK 2025-04-08 1445.0 2025-09-01 | D8: {=_xlfn.TEXTSPLIT(TRIM(B8)," ")} -> 5 | E8: PGAS.JK | F8: 2025-04-08 | G8: 1445.0 | H8: 2025-09-01 | J8: {=_xlfn.TEXTSPLIT(TRIM(B17)," ")} -> 5 | K8: 1665.0 | L8: 2026-04-01 | M8: 1840.0 | N8: =K8/G8-1 -> 0.15224913 | O8: =M8/G8-1 -> 0.2733564
B9: 6 PTBA.JK 2025-04-08 2420.0 2025-09-01 | D9: {=_xlfn.TEXTSPLIT(TRIM(B9)," ")} -> 6 | E9: PTBA.JK | F9: 2025-04-08 | G9: 2420.0 | H9: 2025-09-01 | J9: {=_xlfn.TEXTSPLIT(TRIM(B18)," ")} -> 6 | K9: 2400.0 | L9: 2026-04-01 | M9: 2980.0 | N9: =K9/G9-1 -> -0.0082644628 | O9: =M9/G9-1 -> 0.23140496
B11: Close_2025-09-01 Actual_Date_2026-04-01 Close_2026-04-01
B12: 0 1720.0 2026-04-01 2490.0 | E12: =E2 -> Ticker | F12: =F2 -> Actual_Date_2025-04-01 | G12: =G2 -> Close_2025-04-01 | H12: =H2 -> Actual_Date_2025-09-01 | I12: =I2 -> \ | J12: =J2 -> 0 | K12: =K2 -> Close_2025-09-01 | L12: =L2 -> Actual_Date_2026-04-01 | ... O12: =O2 -> 2025-04-08 VS 2026-04-01 | P12: =Sheet1!H105 -> Rank 2025-04-08 VS 2025-09-01 | Q12: =Sheet1!I105 -> Rank 2025-04-08 VS 2026-04-01
B13: 1 990.0 2026-04-01 2010.0 | E13: =LEFT(E3,4) -> ADRO | F13: =F3 -> 2025-04-08 | G13: =_xlfn.NUMBERVALUE(G3) -> 1645 | H13: =H3 -> 2025-09-01 | I13: =I3 -> 0 | J13: =J3 -> 0 | K13: =_xlfn.NUMBERVALUE(K3) -> 1720 | L13: =L3 -> 2026-04-01 | M13: =_xlfn.NUMBERVALUE(M3) -> 2490 | N13: =N3 -> 0.045592705 | O13: =O3 -> 0.51367781 | P13: =_xlfn.RANK.EQ(N13,$N$13:$N$19) -> 5 | Q13: =_xlfn.RANK.EQ(O13,$O$13:$O$19) -> 3
B14: 2 1190.0 2026-04-01 1345.0 | E14: =LEFT(E4,4) -> ADMR | F14: =F4 -> 2025-04-08 | G14: =_xlfn.NUMBERVALUE(G4) -> 790 | H14: =H4 -> 2025-09-01 | I14: =I4 -> 0 | J14: =J4 -> 1 | K14: =_xlfn.NUMBERVALUE(K4) -> 990 | L14: =L4 -> 2026-04-01 | M14: =_xlfn.NUMBERVALUE(M4) -> 2010 | N14: =N4 -> 0.25316456 | O14: =O4 -> 1.5443038 | P14: =_xlfn.RANK.EQ(N14,$N$13:$N$19) -> 1 | Q14: =_xlfn.RANK.EQ(O14,$O$13:$O$19) -> 1
B15: 3 22200.0 2026-04-01 27775.0 | E15: =LEFT(E5,4) -> AKRA | F15: =F5 -> 2025-04-08 | G15: =_xlfn.NUMBERVALUE(G5) -> 970 | H15: =H5 -> 2025-09-01 | I15: =I5 -> 0 | J15: =J5 -> 2 | K15: =_xlfn.NUMBERVALUE(K5) -> 1190 | L15: =L5 -> 2026-04-01 | M15: =_xlfn.NUMBERVALUE(M5) -> 1345 | N15: =N5 -> 0.22680412 | O15: =O5 -> 0.38659794 | P15: =_xlfn.RANK.EQ(N15,$N$13:$N$19) -> 2 | Q15: =_xlfn.RANK.EQ(O15,$O$13:$O$19) -> 4
B16: 4 1135.0 2026-04-01 1685.0 | E16: =LEFT(E6,4) -> ITMG | F16: =F6 -> 2025-04-08 | G16: =_xlfn.NUMBERVALUE(G6) -> 21825 | H16: =H6 -> 2025-09-01 | I16: =I6 -> 0 | J16: =J6 -> 3 | K16: =_xlfn.NUMBERVALUE(K6) -> 22200 | L16: =L6 -> 2026-04-01 | M16: =_xlfn.NUMBERVALUE(M6) -> 27775 | N16: =N6 -> 0.017182131 | O16: =O6 -> 0.27262314 | P16: =_xlfn.RANK.EQ(N16,$N$13:$N$19) -> 6 | Q16: =_xlfn.RANK.EQ(O16,$O$13:$O$19) -> 6
B17: 5 1665.0 2026-04-01 1840.0 | E17: =LEFT(E7,4) -> MEDC | F17: =F7 -> 2025-04-08 | G17: =_xlfn.NUMBERVALUE(G7) -> 970 | H17: =H7 -> 2025-09-01 | I17: =I7 -> 0 | J17: =J7 -> 4 | K17: =_xlfn.NUMBERVALUE(K7) -> 1135 | L17: =L7 -> 2026-04-01 | M17: =_xlfn.NUMBERVALUE(M7) -> 1685 | N17: =N7 -> 0.17010309 | O17: =O7 -> 0.7371134 | P17: =_xlfn.RANK.EQ(N17,$N$13:$N$19) -> 3 | Q17: =_xlfn.RANK.EQ(O17,$O$13:$O$19) -> 2
B18: 6 2400.0 2026-04-01 2980.0 | E18: =LEFT(E8,4) -> PGAS | F18: =F8 -> 2025-04-08 | G18: =_xlfn.NUMBERVALUE(G8) -> 1445 | H18: =H8 -> 2025-09-01 | I18: =I8 -> 0 | J18: =J8 -> 5 | K18: =_xlfn.NUMBERVALUE(K8) -> 1665 | L18: =L8 -> 2026-04-01 | M18: =_xlfn.NUMBERVALUE(M8) -> 1840 | N18: =N8 -> 0.15224913 | O18: =O8 -> 0.2733564 | P18: =_xlfn.RANK.EQ(N18,$N$13:$N$19) -> 4 | Q18: =_xlfn.RANK.EQ(O18,$O$13:$O$19) -> 5
E19: =LEFT(E9,4) -> PTBA | F19: =F9 -> 2025-04-08 | G19: =_xlfn.NUMBERVALUE(G9) -> 2420 | H19: =H9 -> 2025-09-01 | I19: =I9 -> 0 | J19: =J9 -> 6 | K19: =_xlfn.NUMBERVALUE(K9) -> 2400 | L19: =L9 -> 2026-04-01 | M19: =_xlfn.NUMBERVALUE(M9) -> 2980 | N19: =N9 -> -0.0082644628 | O19: =O9 -> 0.23140496 | P19: =_xlfn.RANK.EQ(N19,$N$13:$N$19) -> 7 | Q19: =_xlfn.RANK.EQ(O19,$O$13:$O$19) -> 7
